Traceback (most recent call last):
  File "/usr/share/miniconda/envs/statsbook/lib/python3.11/site-packages/jupyter_cache/executors/utils.py", line 51, in single_nb_execution
    executenb(
  File "/usr/share/miniconda/envs/statsbook/lib/python3.11/site-packages/nbclient/client.py", line 1204, in execute
    return NotebookClient(nb=nb, resources=resources, km=km, **kwargs).execute()
           ^^^^^^^^^^^^^^^^^^^^^^^^^^^^^^^^^^^^^^^^^^^^^^^^^^^^^^^^^^^^^^^^^^^^^
  File "/usr/share/miniconda/envs/statsbook/lib/python3.11/site-packages/nbclient/util.py", line 84, in wrapped
    return just_run(coro(*args, **kwargs))
           ^^^^^^^^^^^^^^^^^^^^^^^^^^^^^^^
  File "/usr/share/miniconda/envs/statsbook/lib/python3.11/site-packages/nbclient/util.py", line 62, in just_run
    return loop.run_until_complete(coro)
           ^^^^^^^^^^^^^^^^^^^^^^^^^^^^^
  File "/usr/share/miniconda/envs/statsbook/lib/python3.11/asyncio/base_events.py", line 650, in run_until_complete
    return future.result()
           ^^^^^^^^^^^^^^^
  File "/usr/share/miniconda/envs/statsbook/lib/python3.11/contextlib.py", line 222, in __aexit__
    await self.gen.athrow(typ, value, traceback)
  File "/usr/share/miniconda/envs/statsbook/lib/python3.11/site-packages/nbclient/client.py", line 608, in async_setup_kernel
    yield
  File "/usr/share/miniconda/envs/statsbook/lib/python3.11/site-packages/nbclient/client.py", line 663, in async_execute
    await self.async_execute_cell(
  File "/usr/share/miniconda/envs/statsbook/lib/python3.11/site-packages/nbclient/client.py", line 965, in async_execute_cell
    await self._check_raise_for_error(cell, cell_index, exec_reply)
  File "/usr/share/miniconda/envs/statsbook/lib/python3.11/site-packages/nbclient/client.py", line 862, in _check_raise_for_error
    raise CellExecutionError.from_cell_and_msg(cell, exec_reply_content)
nbclient.exceptions.CellExecutionError: An error occurred while executing the following cell:
------------------
from scipy.stats import multinomial
import numpy as np

counts = df["Y"].value_counts()
n_cat = df["Y"].nunique()
multinomial.pmf(xt.values, len(df), np.full(n_cat, 1/n_cat))
------------------

[0;31m---------------------------------------------------------------------------[0m
[0;31mNameError[0m                                 Traceback (most recent call last)
Cell [0;32mIn [4], line 6[0m
[1;32m      4[0m counts [38;5;241m=[39m df[[38;5;124m"[39m[38;5;124mY[39m[38;5;124m"[39m][38;5;241m.[39mvalue_counts()
[1;32m      5[0m n_cat [38;5;241m=[39m df[[38;5;124m"[39m[38;5;124mY[39m[38;5;124m"[39m][38;5;241m.[39mnunique()
[0;32m----> 6[0m multinomial[38;5;241m.[39mpmf([43mxt[49m[38;5;241m.[39mvalues, [38;5;28mlen[39m(df), np[38;5;241m.[39mfull(n_cat, [38;5;241m1[39m[38;5;241m/[39mn_cat))

[0;31mNameError[0m: name 'xt' is not defined
NameError: name 'xt' is not defined

